Workbook
Name scn: Assumptions!$G$6
Name tam_bio: Assumptions!$G$8
Name tam_physio: Assumptions!$G$9
Name tam_pt: Assumptions!$G$10
Name reach_sa: Assumptions!$G$11
Name tam_au_physio: Assumptions!$G$13
Name tam_au_pt: Assumptions!$G$14
Name tam_uk: Assumptions!$G$15
Name tam_nordics: Assumptions!$G$16
Name reach_intl: Assumptions!$G$17
Name intl_start_year: Assumptions!$G$18
Name rev_per_credit: Assumptions!$G$20
Name plans_per_prac: Assumptions!$G$21
Name credits_per_plan: Assumptions!$G$22
Name credit_consume: Assumptions!$G$23
Name signup_rate: Assumptions!$G$25
Name activation: Assumptions!$G$26
Name paid_conv: Assumptions!$G$27
Name ref_invites: Assumptions!$G$28
Name ref_conv: Assumptions!$G$29
Name churn: Assumptions!$G$31
Name early_churn: Assumptions!$G$32
Name warm_y1: Assumptions!$G$34
Name warm_yr: Assumptions!$G$35
Name paid_cac_sa: Assumptions!$G$36
Name paid_cac_intl: Assumptions!$G$37
Name ref_cost: Assumptions!$G$38
Name mix_warm: Assumptions!$G$39
Name mix_paid: Assumptions!$G$40
Name mix_ref: Assumptions!$G$41
Name supabase_base: Assumptions!$G$43
Name supabase_bw: Assumptions!$G$44
Name vercel_base: Assumptions!$G$45
Name vercel_bw: Assumptions!$G$46
Name fx: Assumptions!$G$47
Name domain_yr: Assumptions!$G$48
Name apple_dev_yr: Assumptions!$G$49
Name egress_mb: Assumptions!$G$50
Name pf_pct_early: Assumptions!$G$52
Name pf_pct_late: Assumptions!$G$53
Name pf_fixed: Assumptions!$G$54
Name avg_txn: Assumptions!$G$55
Name vat: Assumptions!$G$56
Name vat_yr: Assumptions!$G$57
Name founder_salary: Assumptions!$G$59
Name salary_growth: Assumptions!$G$60
Name mkt_floor: Assumptions!$G$61
Name mkt_growth: Assumptions!$G$62
Name legal: Assumptions!$G$63
Name hire1_yr: Assumptions!$G$64
Name hire1_sal: Assumptions!$G$65
Name hire2_yr: Assumptions!$G$66
Name hire2_sal: Assumptions!$G$67
Name y5_sa_target: Assumptions!$G$69

Sheet README
A1: homefit.studio — 5-year business case model
A3: Sheet map
A5: Assumptions | B5: Every driver. Pale-coral cells are editable. Toggle scenario at C5 (1/2/3).
A6: Growth | B6: Practitioner funnel — Y1 monthly, Y2–Y5 quarterly.
A7: Revenue | B7: Credit economics → gross / VAT / net / USD.
A8: Costs | B8: Infra + OpEx + COGS.
A9: P&L | B9: Annual rollup. EBITDA per year + 5-yr cumulative.
A10: CashFlow | B10: Period cash flow + running balance (R0 starting).
A11: Scenarios | B11: Unit economics (LTV, CAC, payback). Y5 snapshot of active scenario.
A12: Sensitivity | B12: Tornado scaffold — flex one driver at a time.
A15: Primary sources: see docs/business-case/assumptions-cited.md
A16: Currency: ZAR primary. USD info lines use fx = Assumptions!fx (default R19/USD).
A17: Access date: 2026-04-20

Sheet Assumptions
A1: homefit.studio — 5-Year Business Case
A2: All inputs below are user-editable (pale coral). Everything else is a formula.
A3: Version: v1 · Base date: 2026-04-20 · Horizon: Y1 monthly, Y2–Y5 quarterly
A4: Assumption | B4: Conservative | C4: Base | D4: Optimistic | E4: Unit | F4: Source / note | G4: Active
A5: Scenario selector
A6: Active scenario (1=Conservative, 2=Base, 3=Optimistic) | C6: 2 | E6: int | F6: Driven through the whole model via CHOOSE(). | G6: 2
A7: Market sizing — South Africa
A8: SA registered biokineticists | B8: 2000 | C8: 2400 | D8: 2800 | E8: practitioners | F8: HPCSA+BASA. 2020=1,831 → extrapolated. | G8: =CHOOSE(Assumptions!$C$6, Assumptions!B8, Assumptions!C8, Assumptions!D8)
A9: SA registered physiotherapists | B9: 9000 | C9: 9235 | D9: 9500 | E9: practitioners | F9: HPCSA Mar-2025 = 9,235. | G9: =CHOOSE(Assumptions!$C$6, Assumptions!B9, Assumptions!C9, Assumptions!D9)
A10: SA registered exercise pros (REPSSA+) | B10: 8000 | C10: 11000 | D10: 14000 | E10: practitioners | F10: REPSSA unpublished; derived via SA fitness facility census. | G10: =CHOOSE(Assumptions!$C$6, Assumptions!B10, Assumptions!C10, Assumptions!D10)
A11: Reachable fraction of SA TAM (digital, solo-SMB) | B11: 0.35 | C11: 0.55 | D11: 0.7 | E11: % | F11: Strip public sector / big-chain-locked. | G11: =CHOOSE(Assumptions!$C$6, Assumptions!B11, Assumptions!C11, Assumptions!D11)
A12: Market sizing — International (expansion)
A13: AU physiotherapists | B13: 38000 | C13: 39781 | D13: 41000 | E13: practitioners | F13: Physiotherapy Board of Australia 2024. | G13: =CHOOSE(Assumptions!$C$6, Assumptions!B13, Assumptions!C13, Assumptions!D13)
A14: AUSactive registered exercise pros | B14: 10000 | C14: 11000 | D14: 13000 | E14: practitioners | F14: AUSactive Accreditation page. | G14: =CHOOSE(Assumptions!$C$6, Assumptions!B14, Assumptions!C14, Assumptions!D14)
A15: UK HCPC physiotherapists | B15: 62000 | C15: 64000 | D15: 66000 | E15: practitioners | F15: HCPC Register Summary 2024. | G15: =CHOOSE(Assumptions!$C$6, Assumptions!B15, Assumptions!C15, Assumptions!D15)
A16: Nordics physiotherapists (DK+SE+NO+FI) | B16: 48000 | C16: 50864 | D16: 53000 | E16: practitioners | F16: World Physiotherapy + Statista. | G16: =CHOOSE(Assumptions!$C$6, Assumptions!B16, Assumptions!C16, Assumptions!D16)
A17: Reachable fraction of intl TAM | B17: 0.1 | C17: 0.2 | D17: 0.3 | E17: % | F17: Lower than SA — weaker brand & comp is stronger. | G17: =CHOOSE(Assumptions!$C$6, Assumptions!B17, Assumptions!C17, Assumptions!D17)
A18: International expansion starts in year | B18: 4 | C18: 3 | D18: 2 | E18: year | F18: Y3 base; Y4 conservative; Y2 optimistic. | G18: =CHOOSE(Assumptions!$C$6, Assumptions!B18, Assumptions!C18, Assumptions!D18)
A19: Pricing / revenue
A20: Blended revenue per credit (ZAR, after bundle mix) | B20: 20 | C20: 22.5 | D20: 25 | E20: R/credit | F20: Weighted avg: 10/R250=R25, 50/R1125=R22.50, 200/R4000=R20. | G20: =CHOOSE(Assumptions!$C$6, Assumptions!B20, Assumptions!C20, Assumptions!D20)
A21: Plans published per active practitioner per month | B21: 15 | C21: 35 | D21: 60 | E21: plans/mo | F21: Active = has published ≥1 plan in the month. | G21: =CHOOSE(Assumptions!$C$6, Assumptions!B21, Assumptions!C21, Assumptions!D21)
A22: Avg credits per plan (non-rest count ceil/8, clamped 1-3) | B22: 1.1 | C22: 1.3 | D22: 1.6 | E22: credits | F22: Most plans 1–8 exercises = 1 credit. | G22: =CHOOSE(Assumptions!$C$6, Assumptions!B22, Assumptions!C22, Assumptions!D22)
A23: Credits consumed vs purchased (decay) | B23: 0.75 | C23: 0.85 | D23: 0.95 | E23: % | F23: Some credits sit on account — POPIA retention ceiling. | G23: =CHOOSE(Assumptions!$C$6, Assumptions!B23, Assumptions!C23, Assumptions!D23)
A24: Funnel
A25: Annual signup rate (reachable → signup) | B25: 0.01 | C25: 0.02 | D25: 0.035 | E25: %/yr | F25: Blended across paid+warm+referral. | G25: =CHOOSE(Assumptions!$C$6, Assumptions!B25, Assumptions!C25, Assumptions!D25)
A26: Signup → activation (first published plan) | B26: 0.25 | C26: 0.375 | D26: 0.5 | E26: % | F26: Agile Growth Labs 2025 median 37.5%. | G26: =CHOOSE(Assumptions!$C$6, Assumptions!B26, Assumptions!C26, Assumptions!D26)
A27: Activation → paid (buys 1st bundle) | B27: 0.12 | C27: 0.215 | D27: 0.3 | E27: % | F27: 1Capture Healthcare/MedTech = 21.5%. | G27: =CHOOSE(Assumptions!$C$6, Assumptions!B27, Assumptions!C27, Assumptions!D27)
A28: Referral invites per active per year | B28: 0.15 | C28: 0.35 | D28: 0.6 | E28: inv/yr | F28: Non-cash incentive SaaS. | G28: =CHOOSE(Assumptions!$C$6, Assumptions!B28, Assumptions!C28, Assumptions!D28)
A29: Referee → signup conversion | B29: 0.12 | C29: 0.22 | D29: 0.35 | E29: % | F29: WallStreet Prep viral 15–25% B2B. | G29: =CHOOSE(Assumptions!$C$6, Assumptions!B29, Assumptions!C29, Assumptions!D29)
A30: Churn
A31: Monthly logo churn (steady state) | B31: 0.06 | C31: 0.04 | D31: 0.025 | E31: %/mo | F31: SMB SaaS 3–5%; ours is single-user no-EHR-lock. | G31: =CHOOSE(Assumptions!$C$6, Assumptions!B31, Assumptions!C31, Assumptions!D31)
A32: First-90-day churn uplift (pp) | B32: 0.04 | C32: 0.03 | D32: 0.015 | E32: pp | F32: SMB 90-day concentration. | G32: =CHOOSE(Assumptions!$C$6, Assumptions!B32, Assumptions!C32, Assumptions!D32)
A33: Customer acquisition cost
A34: Warm / organic signups — Y1 total | B34: 40 | C34: 100 | D34: 200 | E34: signups | F34: Melissa's network + BASA talks + early PR. | G34: =CHOOSE(Assumptions!$C$6, Assumptions!B34, Assumptions!C34, Assumptions!D34)
A35: Warm / organic signups — Y2+ per year | B35: 100 | C35: 300 | D35: 600 | E35: signups | F35: CPD talks, conferences, content. | G35: =CHOOSE(Assumptions!$C$6, Assumptions!B35, Assumptions!C35, Assumptions!D35)
A36: Paid CAC — SA | B36: 800 | C36: 520 | D36: 300 | E36: R/signup | F36: LinkedIn+Google mix; CPC R25–45 × CVR 6–8%. | G36: =CHOOSE(Assumptions!$C$6, Assumptions!B36, Assumptions!C36, Assumptions!D36)
A37: Paid CAC — International | B37: 2500 | C37: 1600 | D37: 1000 | E37: R/signup | F37: Est. 3x SA (LinkedIn UK/AU CPCs higher). | G37: =CHOOSE(Assumptions!$C$6, Assumptions!B37, Assumptions!C37, Assumptions!D37)
A38: Referral variable cost (free-credit value) | B38: 80 | C38: 50 | D38: 30 | E38: R/signup | F38: 8 free credits × R20/credit cost basis × goodwill haircut. | G38: =CHOOSE(Assumptions!$C$6, Assumptions!B38, Assumptions!C38, Assumptions!D38)
A39: Mix: warm share | B39: 0.35 | C39: 0.5 | D39: 0.6 | E39: % | F39: Falls over time — base case decays 5pp/yr. | G39: =CHOOSE(Assumptions!$C$6, Assumptions!B39, Assumptions!C39, Assumptions!D39)
A40: Mix: paid share | B40: 0.45 | C40: 0.3 | D40: 0.2 | E40: % | F40: Rises when warm runs out. | G40: =CHOOSE(Assumptions!$C$6, Assumptions!B40, Assumptions!C40, Assumptions!D40)
...

Sheet Growth
A1: Practitioner growth — monthly Y1, quarterly Y2–Y5
A2: Paying practitioners drive revenue on Sheet 3. All rates come from Assumptions.
A4: Metric | B4: Y1 M1 | C4: Y1 M2 | D4: Y1 M3 | E4: Y1 M4 | F4: Y1 M5 | G4: Y1 M6 | H4: Y1 M7 | I4: Y1 M8 | J4: Y1 M9 | K4: Y1 M10 | L4: Y1 M11 | M4: Y1 M12 | N4: Y2 Q1 | O4: Y2 Q2 | P4: Y2 Q3 | Q4: Y2 Q4 | R4: Y3 Q1 | S4: Y3 Q2 | T4: Y3 Q3 | U4: Y3 Q4 | V4: Y4 Q1 | W4: Y4 Q2 | X4: Y4 Q3 | Y4: Y4 Q4 | Z4: Y5 Q1 | AA4: Y5 Q2 | AB4: Y5 Q3 | AC4: Y5 Q4
A5: SA TAM (practitioners) | B5: =(tam_bio+tam_physio+tam_pt)*(1.02)^(B21-1) | C5: =(tam_bio+tam_physio+tam_pt)*(1.02)^(C21-1) | D5: =(tam_bio+tam_physio+tam_pt)*(1.02)^(D21-1) | E5: =(tam_bio+tam_physio+tam_pt)*(1.02)^(E21-1) | F5: =(tam_bio+tam_physio+tam_pt)*(1.02)^(F21-1) | G5: =(tam_bio+tam_physio+tam_pt)*(1.02)^(G21-1) | H5: =(tam_bio+tam_physio+tam_pt)*(1.02)^(H21-1) | I5: =(tam_bio+tam_physio+tam_pt)*(1.02)^(I21-1) | ... AC5: =(tam_bio+tam_physio+tam_pt)*(1.02)^(AC21-1)
A6: SA reachable | B6: =B5*reach_sa | C6: =C5*reach_sa | D6: =D5*reach_sa | E6: =E5*reach_sa | F6: =F5*reach_sa | G6: =G5*reach_sa | H6: =H5*reach_sa | I6: =I5*reach_sa | ... AC6: =AC5*reach_sa
A7: International TAM | B7: =(tam_au_physio+tam_au_pt+tam_uk+tam_nordics)*(1.015)^(B21-1) | C7: =(tam_au_physio+tam_au_pt+tam_uk+tam_nordics)*(1.015)^(C21-1) | D7: =(tam_au_physio+tam_au_pt+tam_uk+tam_nordics)*(1.015)^(D21-1) | E7: =(tam_au_physio+tam_au_pt+tam_uk+tam_nordics)*(1.015)^(E21-1) | F7: =(tam_au_physio+tam_au_pt+tam_uk+tam_nordics)*(1.015)^(F21-1) | G7: =(tam_au_physio+tam_au_pt+tam_uk+tam_nordics)*(1.015)^(G21-1) | H7: =(tam_au_physio+tam_au_pt+tam_uk+tam_nordics)*(1.015)^(H21-1) | I7: =(tam_au_physio+tam_au_pt+tam_uk+tam_nordics)*(1.015)^(I21-1) | ... AC7: =(tam_au_physio+tam_au_pt+tam_uk+tam_nordics)*(1.015)^(AC21-1)
A8: International reachable (when active) | B8: =B7*reach_intl*B22 | C8: =C7*reach_intl*C22 | D8: =D7*reach_intl*D22 | E8: =E7*reach_intl*E22 | F8: =F7*reach_intl*F22 | G8: =G7*reach_intl*G22 | H8: =H7*reach_intl*H22 | I8: =I7*reach_intl*I22 | ... AC8: =AC7*reach_intl*AC22
A9: Total reachable | B9: =B6+B8 | C9: =C6+C8 | D9: =D6+D8 | E9: =E6+E8 | F9: =F6+F8 | G9: =G6+G8 | H9: =H6+H8 | I9: =I6+I8 | ... AC9: =AC6+AC8
A10: Cumulative signups (start of period) | B10: 0 | C10: =B10+B11 | D10: =C10+C11 | E10: =D10+D11 | F10: =E10+E11 | G10: =F10+F11 | H10: =G10+G11 | I10: =H10+H11 | J10: =I10+I11 | ... AC10: =AB10+AB11
A11: New signups (period) | B11: =warm_y1/12+MAX(0,(B9-B10))*signup_rate*B20+B16*ref_invites*ref_conv*B20 | C11: =warm_y1/12+MAX(0,(C9-C10))*signup_rate*C20+B16*ref_invites*ref_conv*C20 | D11: =warm_y1/12+MAX(0,(D9-D10))*signup_rate*D20+C16*ref_invites*ref_conv*D20 | E11: =warm_y1/12+MAX(0,(E9-E10))*signup_rate*E20+D16*ref_invites*ref_conv*E20 | F11: =warm_y1/12+MAX(0,(F9-F10))*signup_rate*F20+E16*ref_invites*ref_conv*F20 | G11: =warm_y1/12+MAX(0,(G9-G10))*signup_rate*G20+F16*ref_invites*ref_conv*G20 | H11: =warm_y1/12+MAX(0,(H9-H10))*signup_rate*H20+G16*ref_invites*ref_conv*H20 | I11: =warm_y1/12+MAX(0,(I9-I10))*signup_rate*I20+H16*ref_invites*ref_conv*I20 | J11: =warm_y1/12+MAX(0,(J9-J10))*signup_rate*J20+I16*ref_invites*ref_conv*J20 | ... M11: =warm_y1/12+MAX(0,(M9-M10))*signup_rate*M20+L16*ref_invites*ref_conv*M20 | N11: =warm_yr/4+MAX(0,(N9-N10))*signup_rate*N20+M16*ref_invites*ref_conv*N20 | O11: =warm_yr/4+MAX(0,(O9-O10))*signup_rate*O20+N16*ref_invites*ref_conv*O20 | P11: =warm_yr/4+MAX(0,(P9-P10))*signup_rate*P20+O16*ref_invites*ref_conv*P20 | Q11: =warm_yr/4+MAX(0,(Q9-Q10))*signup_rate*Q20+P16*ref_invites*ref_conv*Q20 | R11: =warm_yr/4+MAX(0,(R9-R10))*signup_rate*R20+Q16*ref_invites*ref_conv*R20 | S11: =warm_yr/4+MAX(0,(S9-S10))*signup_rate*S20+R16*ref_invites*ref_conv*S20 | T11: =warm_yr/4+MAX(0,(T9-T10))*signup_rate*T20+S16*ref_invites*ref_conv*T20 | U11: =warm_yr/4+MAX(0,(U9-U10))*signup_rate*U20+T16*ref_invites*ref_conv*U20 | ... AC11: =warm_yr/4+MAX(0,(AC9-AC10))*signup_rate*AC20+AB16*ref_invites*ref_conv*AC20
A12: New activations | B12: =B11*activation | C12: =C11*activation | D12: =D11*activation | E12: =E11*activation | F12: =F11*activation | G12: =G11*activation | H12: =H11*activation | I12: =I11*activation | ... AC12: =AC11*activation
A13: New paying | B13: =B12*paid_conv | C13: =C12*paid_conv | D13: =D12*paid_conv | E13: =E12*paid_conv | F13: =F12*paid_conv | G13: =G12*paid_conv | H13: =H12*paid_conv | I13: =I12*paid_conv | ... AC13: =AC12*paid_conv
A14: Churned paying | B14: 0 | C14: =B16*churn | D14: =C16*churn | E14: =D16*churn | F14: =E16*churn | G14: =F16*churn | H14: =G16*churn | I14: =H16*churn | J14: =I16*churn | ... M14: =L16*churn | N14: =M16*(1-(1-churn)^3) | O14: =N16*(1-(1-churn)^3) | P14: =O16*(1-(1-churn)^3) | Q14: =P16*(1-(1-churn)^3) | R14: =Q16*(1-(1-churn)^3) | S14: =R16*(1-(1-churn)^3) | T14: =S16*(1-(1-churn)^3) | U14: =T16*(1-(1-churn)^3) | ... AC14: =AB16*(1-(1-churn)^3)
A15: Net new paying | B15: =B13-B14 | C15: =C13-C14 | D15: =D13-D14 | E15: =E13-E14 | F15: =F13-F14 | G15: =G13-G14 | H15: =H13-H14 | I15: =I13-I14 | ... AC15: =AC13-AC14
A16: Cumulative paying (end of period) | B16: =B15 | C16: =B16+C15 | D16: =C16+D15 | E16: =D16+E15 | F16: =E16+F15 | G16: =F16+G15 | H16: =G16+H15 | I16: =H16+I15 | J16: =I16+J15 | ... AC16: =AB16+AC15
A17: Active paying (publishing) in period | B17: =B16 | C17: =C16 | D17: =D16 | E17: =E16 | F17: =F16 | G17: =G16 | H17: =H16 | I17: =I16 | ... AC17: =AC16
A18: Referral invites generated | B18: =B17*ref_invites*B20 | C18: =C17*ref_invites*C20 | D18: =D17*ref_invites*D20 | E18: =E17*ref_invites*E20 | F18: =F17*ref_invites*F20 | G18: =G17*ref_invites*G20 | H18: =H17*ref_invites*H20 | I18: =I17*ref_invites*I20 | ... AC18: =AC17*ref_invites*AC20
A19: Referrals that signed up | B19: =B18*ref_conv | C19: =C18*ref_conv | D19: =D18*ref_conv | E19: =E18*ref_conv | F19: =F18*ref_conv | G19: =G18*ref_conv | H19: =H18*ref_conv | I19: =I18*ref_conv | ... AC19: =AC18*ref_conv
A20: Fraction-of-year | B20: 0.083333333 | C20: 0.083333333 | D20: 0.083333333 | E20: 0.083333333 | F20: 0.083333333 | G20: 0.083333333 | H20: 0.083333333 | I20: 0.083333333 | J20: 0.083333333 | K20: 0.083333333 | L20: 0.083333333 | M20: 0.083333333 | N20: 0.25 | O20: 0.25 | P20: 0.25 | Q20: 0.25 | R20: 0.25 | S20: 0.25 | T20: 0.25 | U20: 0.25 | V20: 0.25 | W20: 0.25 | X20: 0.25 | Y20: 0.25 | Z20: 0.25 | AA20: 0.25 | AB20: 0.25 | AC20: 0.25
A21: (helper) Year number of this period | B21: 1 | C21: 1 | D21: 1 | E21: 1 | F21: 1 | G21: 1 | H21: 1 | I21: 1 | J21: 1 | K21: 1 | L21: 1 | M21: 1 | N21: 2 | O21: 2 | P21: 2 | Q21: 2 | R21: 3 | S21: 3 | T21: 3 | U21: 3 | V21: 4 | W21: 4 | X21: 4 | Y21: 4 | Z21: 5 | AA21: 5 | AB21: 5 | AC21: 5
A22: (helper) Is intl active? 0/1 | B22: =IF(B21>=intl_start_year,1,0) | C22: =IF(C21>=intl_start_year,1,0) | D22: =IF(D21>=intl_start_year,1,0) | E22: =IF(E21>=intl_start_year,1,0) | F22: =IF(F21>=intl_start_year,1,0) | G22: =IF(G21>=intl_start_year,1,0) | H22: =IF(H21>=intl_start_year,1,0) | I22: =IF(I21>=intl_start_year,1,0) | ... AC22: =IF(AC21>=intl_start_year,1,0)

Sheet Revenue
A1: Revenue — credit economics
A2: Active-paying × plans/month × credits/plan × R/credit × consume rate = gross.
A4: Metric | B4: Y1 M1 | C4: Y1 M2 | D4: Y1 M3 | E4: Y1 M4 | F4: Y1 M5 | G4: Y1 M6 | H4: Y1 M7 | I4: Y1 M8 | J4: Y1 M9 | K4: Y1 M10 | L4: Y1 M11 | M4: Y1 M12 | N4: Y2 Q1 | O4: Y2 Q2 | P4: Y2 Q3 | Q4: Y2 Q4 | R4: Y3 Q1 | S4: Y3 Q2 | T4: Y3 Q3 | U4: Y3 Q4 | V4: Y4 Q1 | W4: Y4 Q2 | X4: Y4 Q3 | Y4: Y4 Q4 | Z4: Y5 Q1 | AA4: Y5 Q2 | AB4: Y5 Q3 | AC4: Y5 Q4
A5: Active paying practitioners | B5: =Growth!B17 | C5: =Growth!C17 | D5: =Growth!D17 | E5: =Growth!E17 | F5: =Growth!F17 | G5: =Growth!G17 | H5: =Growth!H17 | I5: =Growth!I17 | ... AC5: =Growth!AC17
A6: Plans published in period | B6: =B5*plans_per_prac*1 | C6: =C5*plans_per_prac*1 | D6: =D5*plans_per_prac*1 | E6: =E5*plans_per_prac*1 | F6: =F5*plans_per_prac*1 | G6: =G5*plans_per_prac*1 | H6: =H5*plans_per_prac*1 | I6: =I5*plans_per_prac*1 | ... M6: =M5*plans_per_prac*1 | N6: =N5*plans_per_prac*3 | O6: =O5*plans_per_prac*3 | P6: =P5*plans_per_prac*3 | Q6: =Q5*plans_per_prac*3 | R6: =R5*plans_per_prac*3 | S6: =S5*plans_per_prac*3 | T6: =T5*plans_per_prac*3 | U6: =U5*plans_per_prac*3 | ... AC6: =AC5*plans_per_prac*3
A7: Credits consumed in period | B7: =B6*credits_per_plan | C7: =C6*credits_per_plan | D7: =D6*credits_per_plan | E7: =E6*credits_per_plan | F7: =F6*credits_per_plan | G7: =G6*credits_per_plan | H7: =H6*credits_per_plan | I7: =I6*credits_per_plan | ... AC7: =AC6*credits_per_plan
A8: Credit purchases in period (≥ consumed) | B8: =B7/credit_consume | C8: =C7/credit_consume | D8: =D7/credit_consume | E8: =E7/credit_consume | F8: =F7/credit_consume | G8: =G7/credit_consume | H8: =H7/credit_consume | I8: =I7/credit_consume | ... AC8: =AC7/credit_consume
A9: Gross revenue (ZAR, VAT-incl.) | B9: =B8*rev_per_credit | C9: =C8*rev_per_credit | D9: =D8*rev_per_credit | E9: =E8*rev_per_credit | F9: =F8*rev_per_credit | G9: =G8*rev_per_credit | H9: =H8*rev_per_credit | I9: =I8*rev_per_credit | ... AC9: =AC8*rev_per_credit
A10: VAT collected (paid to SARS when registered) | B10: =IF(Growth!B21>=vat_yr,B9*vat/(1+vat),0) | C10: =IF(Growth!C21>=vat_yr,C9*vat/(1+vat),0) | D10: =IF(Growth!D21>=vat_yr,D9*vat/(1+vat),0) | E10: =IF(Growth!E21>=vat_yr,E9*vat/(1+vat),0) | F10: =IF(Growth!F21>=vat_yr,F9*vat/(1+vat),0) | G10: =IF(Growth!G21>=vat_yr,G9*vat/(1+vat),0) | H10: =IF(Growth!H21>=vat_yr,H9*vat/(1+vat),0) | I10: =IF(Growth!I21>=vat_yr,I9*vat/(1+vat),0) | ... AC10: =IF(Growth!AC21>=vat_yr,AC9*vat/(1+vat),0)
A11: Net revenue ex-VAT (ZAR) | B11: =B9-B10 | C11: =C9-C10 | D11: =D9-D10 | E11: =E9-E10 | F11: =F9-F10 | G11: =G9-G10 | H11: =H9-H10 | I11: =I9-I10 | ... AC11: =AC9-AC10
A12: Transaction count (est.) | B12: =B9/avg_txn | C12: =C9/avg_txn | D12: =D9/avg_txn | E12: =E9/avg_txn | F12: =F9/avg_txn | G12: =G9/avg_txn | H12: =H9/avg_txn | I12: =I9/avg_txn | ... AC12: =AC9/avg_txn
A13: PayFast processing fee (ZAR) | B13: =B9*IF(Growth!B21<=2,pf_pct_early,pf_pct_late)+B12*pf_fixed | C13: =C9*IF(Growth!C21<=2,pf_pct_early,pf_pct_late)+C12*pf_fixed | D13: =D9*IF(Growth!D21<=2,pf_pct_early,pf_pct_late)+D12*pf_fixed | E13: =E9*IF(Growth!E21<=2,pf_pct_early,pf_pct_late)+E12*pf_fixed | F13: =F9*IF(Growth!F21<=2,pf_pct_early,pf_pct_late)+F12*pf_fixed | G13: =G9*IF(Growth!G21<=2,pf_pct_early,pf_pct_late)+G12*pf_fixed | H13: =H9*IF(Growth!H21<=2,pf_pct_early,pf_pct_late)+H12*pf_fixed | I13: =I9*IF(Growth!I21<=2,pf_pct_early,pf_pct_late)+I12*pf_fixed | ... AC13: =AC9*IF(Growth!AC21<=2,pf_pct_early,pf_pct_late)+AC12*pf_fixed
A14: Net revenue after PayFast + VAT (ZAR) | B14: =B11-B13 | C14: =C11-C13 | D14: =D11-D13 | E14: =E11-E13 | F14: =F11-F13 | G14: =G11-G13 | H14: =H11-H13 | I14: =I11-I13 | ... AC14: =AC11-AC13
A15: Gross USD (info) | B15: =B9/fx | C15: =C9/fx | D15: =D9/fx | E15: =E9/fx | F15: =F9/fx | G15: =G9/fx | H15: =H9/fx | I15: =I9/fx | ... AC15: =AC9/fx

Sheet Costs
A1: Costs — infra, marketing, OpEx
A4: Metric | B4: Y1 M1 | C4: Y1 M2 | D4: Y1 M3 | E4: Y1 M4 | F4: Y1 M5 | G4: Y1 M6 | H4: Y1 M7 | I4: Y1 M8 | J4: Y1 M9 | K4: Y1 M10 | L4: Y1 M11 | M4: Y1 M12 | N4: Y2 Q1 | O4: Y2 Q2 | P4: Y2 Q3 | Q4: Y2 Q4 | R4: Y3 Q1 | S4: Y3 Q2 | T4: Y3 Q3 | U4: Y3 Q4 | V4: Y4 Q1 | W4: Y4 Q2 | X4: Y4 Q3 | Y4: Y4 Q4 | Z4: Y5 Q1 | AA4: Y5 Q2 | AB4: Y5 Q3 | AC4: Y5 Q4
A5: Active paying practitioners (ref) | B5: =Growth!B17 | C5: =Growth!C17 | D5: =Growth!D17 | E5: =Growth!E17 | F5: =Growth!F17 | G5: =Growth!G17 | H5: =Growth!H17 | I5: =Growth!I17 | ... AC5: =Growth!AC17
A6: Infra: Supabase Pro base (ZAR) | B6: =supabase_base*fx*1 | C6: =supabase_base*fx*1 | D6: =supabase_base*fx*1 | E6: =supabase_base*fx*1 | F6: =supabase_base*fx*1 | G6: =supabase_base*fx*1 | H6: =supabase_base*fx*1 | I6: =supabase_base*fx*1 | ... M6: =supabase_base*fx*1 | N6: =supabase_base*fx*3 | O6: =supabase_base*fx*3 | P6: =supabase_base*fx*3 | Q6: =supabase_base*fx*3 | R6: =supabase_base*fx*3 | S6: =supabase_base*fx*3 | T6: =supabase_base*fx*3 | U6: =supabase_base*fx*3 | ... AC6: =supabase_base*fx*3
A7: Infra: Supabase bandwidth (ZAR) | B7: =B5*egress_mb/1024*supabase_bw*fx*1 | C7: =C5*egress_mb/1024*supabase_bw*fx*1 | D7: =D5*egress_mb/1024*supabase_bw*fx*1 | E7: =E5*egress_mb/1024*supabase_bw*fx*1 | F7: =F5*egress_mb/1024*supabase_bw*fx*1 | G7: =G5*egress_mb/1024*supabase_bw*fx*1 | H7: =H5*egress_mb/1024*supabase_bw*fx*1 | I7: =I5*egress_mb/1024*supabase_bw*fx*1 | ... M7: =M5*egress_mb/1024*supabase_bw*fx*1 | N7: =N5*egress_mb/1024*supabase_bw*fx*3 | O7: =O5*egress_mb/1024*supabase_bw*fx*3 | P7: =P5*egress_mb/1024*supabase_bw*fx*3 | Q7: =Q5*egress_mb/1024*supabase_bw*fx*3 | R7: =R5*egress_mb/1024*supabase_bw*fx*3 | S7: =S5*egress_mb/1024*supabase_bw*fx*3 | T7: =T5*egress_mb/1024*supabase_bw*fx*3 | U7: =U5*egress_mb/1024*supabase_bw*fx*3 | ... AC7: =AC5*egress_mb/1024*supabase_bw*fx*3
A8: Infra: Vercel Pro (ZAR) | B8: =vercel_base*fx*1 | C8: =vercel_base*fx*1 | D8: =vercel_base*fx*1 | E8: =vercel_base*fx*1 | F8: =vercel_base*fx*1 | G8: =vercel_base*fx*1 | H8: =vercel_base*fx*1 | I8: =vercel_base*fx*1 | ... M8: =vercel_base*fx*1 | N8: =vercel_base*fx*3 | O8: =vercel_base*fx*3 | P8: =vercel_base*fx*3 | Q8: =vercel_base*fx*3 | R8: =vercel_base*fx*3 | S8: =vercel_base*fx*3 | T8: =vercel_base*fx*3 | U8: =vercel_base*fx*3 | ... AC8: =vercel_base*fx*3
A9: Infra: Domain + Apple Dev amortised (ZAR) | B9: =(domain_yr+apple_dev_yr*fx)/12*1 | C9: =(domain_yr+apple_dev_yr*fx)/12*1 | D9: =(domain_yr+apple_dev_yr*fx)/12*1 | E9: =(domain_yr+apple_dev_yr*fx)/12*1 | F9: =(domain_yr+apple_dev_yr*fx)/12*1 | G9: =(domain_yr+apple_dev_yr*fx)/12*1 | H9: =(domain_yr+apple_dev_yr*fx)/12*1 | I9: =(domain_yr+apple_dev_yr*fx)/12*1 | ... M9: =(domain_yr+apple_dev_yr*fx)/12*1 | N9: =(domain_yr+apple_dev_yr*fx)/12*3 | O9: =(domain_yr+apple_dev_yr*fx)/12*3 | P9: =(domain_yr+apple_dev_yr*fx)/12*3 | Q9: =(domain_yr+apple_dev_yr*fx)/12*3 | R9: =(domain_yr+apple_dev_yr*fx)/12*3 | S9: =(domain_yr+apple_dev_yr*fx)/12*3 | T9: =(domain_yr+apple_dev_yr*fx)/12*3 | U9: =(domain_yr+apple_dev_yr*fx)/12*3 | ... AC9: =(domain_yr+apple_dev_yr*fx)/12*3
A10: Infra subtotal (ZAR) | B10: =SUM(B6:B9) | C10: =SUM(C6:C9) | D10: =SUM(D6:D9) | E10: =SUM(E6:E9) | F10: =SUM(F6:F9) | G10: =SUM(G6:G9) | H10: =SUM(H6:H9) | I10: =SUM(I6:I9) | ... AC10: =SUM(AC6:AC9)
A11: Marketing spend (ZAR) | B11: =mkt_floor*(1+mkt_growth)^(Growth!B21-1)*1 | C11: =mkt_floor*(1+mkt_growth)^(Growth!C21-1)*1 | D11: =mkt_floor*(1+mkt_growth)^(Growth!D21-1)*1 | E11: =mkt_floor*(1+mkt_growth)^(Growth!E21-1)*1 | F11: =mkt_floor*(1+mkt_growth)^(Growth!F21-1)*1 | G11: =mkt_floor*(1+mkt_growth)^(Growth!G21-1)*1 | H11: =mkt_floor*(1+mkt_growth)^(Growth!H21-1)*1 | I11: =mkt_floor*(1+mkt_growth)^(Growth!I21-1)*1 | ... M11: =mkt_floor*(1+mkt_growth)^(Growth!M21-1)*1 | N11: =mkt_floor*(1+mkt_growth)^(Growth!N21-1)*3 | O11: =mkt_floor*(1+mkt_growth)^(Growth!O21-1)*3 | P11: =mkt_floor*(1+mkt_growth)^(Growth!P21-1)*3 | Q11: =mkt_floor*(1+mkt_growth)^(Growth!Q21-1)*3 | R11: =mkt_floor*(1+mkt_growth)^(Growth!R21-1)*3 | S11: =mkt_floor*(1+mkt_growth)^(Growth!S21-1)*3 | T11: =mkt_floor*(1+mkt_growth)^(Growth!T21-1)*3 | U11: =mkt_floor*(1+mkt_growth)^(Growth!U21-1)*3 | ... AC11: =mkt_floor*(1+mkt_growth)^(Growth!AC21-1)*3
A12: Legal / accounting (ZAR) | B12: =legal*1 | C12: =legal*1 | D12: =legal*1 | E12: =legal*1 | F12: =legal*1 | G12: =legal*1 | H12: =legal*1 | I12: =legal*1 | ... M12: =legal*1 | N12: =legal*3 | O12: =legal*3 | P12: =legal*3 | Q12: =legal*3 | R12: =legal*3 | S12: =legal*3 | T12: =legal*3 | U12: =legal*3 | ... AC12: =legal*3
A13: Founder salary (Carl) (ZAR) | B13: =founder_salary*(1+salary_growth)^(Growth!B21-1)*1 | C13: =founder_salary*(1+salary_growth)^(Growth!C21-1)*1 | D13: =founder_salary*(1+salary_growth)^(Growth!D21-1)*1 | E13: =founder_salary*(1+salary_growth)^(Growth!E21-1)*1 | F13: =founder_salary*(1+salary_growth)^(Growth!F21-1)*1 | G13: =founder_salary*(1+salary_growth)^(Growth!G21-1)*1 | H13: =founder_salary*(1+salary_growth)^(Growth!H21-1)*1 | I13: =founder_salary*(1+salary_growth)^(Growth!I21-1)*1 | ... M13: =founder_salary*(1+salary_growth)^(Growth!M21-1)*1 | N13: =founder_salary*(1+salary_growth)^(Growth!N21-1)*3 | O13: =founder_salary*(1+salary_growth)^(Growth!O21-1)*3 | P13: =founder_salary*(1+salary_growth)^(Growth!P21-1)*3 | Q13: =founder_salary*(1+salary_growth)^(Growth!Q21-1)*3 | R13: =founder_salary*(1+salary_growth)^(Growth!R21-1)*3 | S13: =founder_salary*(1+salary_growth)^(Growth!S21-1)*3 | T13: =founder_salary*(1+salary_growth)^(Growth!T21-1)*3 | U13: =founder_salary*(1+salary_growth)^(Growth!U21-1)*3 | ... AC13: =founder_salary*(1+salary_growth)^(Growth!AC21-1)*3
A14: Hire 1 — Customer success (ZAR) | B14: =IF(AND(hire1_yr>0,Growth!B21>=hire1_yr),hire1_sal*1,0) | C14: =IF(AND(hire1_yr>0,Growth!C21>=hire1_yr),hire1_sal*1,0) | D14: =IF(AND(hire1_yr>0,Growth!D21>=hire1_yr),hire1_sal*1,0) | E14: =IF(AND(hire1_yr>0,Growth!E21>=hire1_yr),hire1_sal*1,0) | F14: =IF(AND(hire1_yr>0,Growth!F21>=hire1_yr),hire1_sal*1,0) | G14: =IF(AND(hire1_yr>0,Growth!G21>=hire1_yr),hire1_sal*1,0) | H14: =IF(AND(hire1_yr>0,Growth!H21>=hire1_yr),hire1_sal*1,0) | I14: =IF(AND(hire1_yr>0,Growth!I21>=hire1_yr),hire1_sal*1,0) | ... M14: =IF(AND(hire1_yr>0,Growth!M21>=hire1_yr),hire1_sal*1,0) | N14: =IF(AND(hire1_yr>0,Growth!N21>=hire1_yr),hire1_sal*3,0) | O14: =IF(AND(hire1_yr>0,Growth!O21>=hire1_yr),hire1_sal*3,0) | P14: =IF(AND(hire1_yr>0,Growth!P21>=hire1_yr),hire1_sal*3,0) | Q14: =IF(AND(hire1_yr>0,Growth!Q21>=hire1_yr),hire1_sal*3,0) | R14: =IF(AND(hire1_yr>0,Growth!R21>=hire1_yr),hire1_sal*3,0) | S14: =IF(AND(hire1_yr>0,Growth!S21>=hire1_yr),hire1_sal*3,0) | T14: =IF(AND(hire1_yr>0,Growth!T21>=hire1_yr),hire1_sal*3,0) | U14: =IF(AND(hire1_yr>0,Growth!U21>=hire1_yr),hire1_sal*3,0) | ... AC14: =IF(AND(hire1_yr>0,Growth!AC21>=hire1_yr),hire1_sal*3,0)
A15: Hire 2 — Engineer (ZAR) | B15: =IF(AND(hire2_yr>0,Growth!B21>=hire2_yr),hire2_sal*1,0) | C15: =IF(AND(hire2_yr>0,Growth!C21>=hire2_yr),hire2_sal*1,0) | D15: =IF(AND(hire2_yr>0,Growth!D21>=hire2_yr),hire2_sal*1,0) | E15: =IF(AND(hire2_yr>0,Growth!E21>=hire2_yr),hire2_sal*1,0) | F15: =IF(AND(hire2_yr>0,Growth!F21>=hire2_yr),hire2_sal*1,0) | G15: =IF(AND(hire2_yr>0,Growth!G21>=hire2_yr),hire2_sal*1,0) | H15: =IF(AND(hire2_yr>0,Growth!H21>=hire2_yr),hire2_sal*1,0) | I15: =IF(AND(hire2_yr>0,Growth!I21>=hire2_yr),hire2_sal*1,0) | ... M15: =IF(AND(hire2_yr>0,Growth!M21>=hire2_yr),hire2_sal*1,0) | N15: =IF(AND(hire2_yr>0,Growth!N21>=hire2_yr),hire2_sal*3,0) | O15: =IF(AND(hire2_yr>0,Growth!O21>=hire2_yr),hire2_sal*3,0) | P15: =IF(AND(hire2_yr>0,Growth!P21>=hire2_yr),hire2_sal*3,0) | Q15: =IF(AND(hire2_yr>0,Growth!Q21>=hire2_yr),hire2_sal*3,0) | R15: =IF(AND(hire2_yr>0,Growth!R21>=hire2_yr),hire2_sal*3,0) | S15: =IF(AND(hire2_yr>0,Growth!S21>=hire2_yr),hire2_sal*3,0) | T15: =IF(AND(hire2_yr>0,Growth!T21>=hire2_yr),hire2_sal*3,0) | U15: =IF(AND(hire2_yr>0,Growth!U21>=hire2_yr),hire2_sal*3,0) | ... AC15: =IF(AND(hire2_yr>0,Growth!AC21>=hire2_yr),hire2_sal*3,0)
A16: OpEx subtotal (ZAR) | B16: =SUM(B11:B15) | C16: =SUM(C11:C15) | D16: =SUM(D11:D15) | E16: =SUM(E11:E15) | F16: =SUM(F11:F15) | G16: =SUM(G11:G15) | H16: =SUM(H11:H15) | I16: =SUM(I11:I15) | ... AC16: =SUM(AC11:AC15)
A17: COGS (PayFast fees, ref) | B17: =Revenue!B13 | C17: =Revenue!C13 | D17: =Revenue!D13 | E17: =Revenue!E13 | F17: =Revenue!F13 | G17: =Revenue!G13 | H17: =Revenue!H13 | I17: =Revenue!I13 | ... AC17: =Revenue!AC13
A18: Total costs (ZAR) | B18: =B10+B16+B17 | C18: =C10+C16+C17 | D18: =D10+D16+D17 | E18: =E10+E16+E17 | F18: =F10+F16+F17 | G18: =G10+G16+G17 | H18: =H10+H16+H17 | I18: =I10+I16+I17 | ... AC18: =AC10+AC16+AC17
A19: Total costs USD (info) | B19: =B18/fx | C19: =C18/fx | D19: =D18/fx | E19: =E18/fx | F19: =F18/fx | G19: =G18/fx | H19: =H18/fx | I19: =I18/fx | ... AC19: =AC18/fx

Sheet P&L
A1: Annual P&L (ZAR)
A4: Line item | B4: Year 1 | C4: Year 2 | D4: Year 3 | E4: Year 4 | F4: Year 5 | G4: 5-yr total
A5: Active paying (end-of-year) | B5: =Growth!M16 | C5: =Growth!Q16 | D5: =Growth!U16 | E5: =Growth!Y16 | F5: =Growth!AC16 | G5: =SUM(B5:F5)
A6: Gross revenue (ZAR, VAT-incl.) | B6: =SUM(Revenue!B9:M9) | C6: =SUM(Revenue!N9:Q9) | D6: =SUM(Revenue!R9:U9) | E6: =SUM(Revenue!V9:Y9) | F6: =SUM(Revenue!Z9:AC9) | G6: =SUM(B6:F6)
A7: Less: VAT | B7: =-SUM(Revenue!B10:M10) | C7: =-SUM(Revenue!N10:Q10) | D7: =-SUM(Revenue!R10:U10) | E7: =-SUM(Revenue!V10:Y10) | F7: =-SUM(Revenue!Z10:AC10) | G7: =SUM(B7:F7)
A8: Net revenue ex-VAT | B8: =SUM(Revenue!B11:M11) | C8: =SUM(Revenue!N11:Q11) | D8: =SUM(Revenue!R11:U11) | E8: =SUM(Revenue!V11:Y11) | F8: =SUM(Revenue!Z11:AC11) | G8: =SUM(B8:F8)
A9: Less: PayFast fees (COGS) | B9: =-SUM(Revenue!B13:M13) | C9: =-SUM(Revenue!N13:Q13) | D9: =-SUM(Revenue!R13:U13) | E9: =-SUM(Revenue!V13:Y13) | F9: =-SUM(Revenue!Z13:AC13) | G9: =SUM(B9:F9)
A10: Gross profit | B10: =SUM(Revenue!B14:M14) | C10: =SUM(Revenue!N14:Q14) | D10: =SUM(Revenue!R14:U14) | E10: =SUM(Revenue!V14:Y14) | F10: =SUM(Revenue!Z14:AC14) | G10: =SUM(B10:F10)
A11: Gross margin % | B11: =SUM(Revenue!B14:M14)/MAX(SUM(Revenue!B11:M11),1) | C11: =SUM(Revenue!N14:Q14)/MAX(SUM(Revenue!N11:Q11),1) | D11: =SUM(Revenue!R14:U14)/MAX(SUM(Revenue!R11:U11),1) | E11: =SUM(Revenue!V14:Y14)/MAX(SUM(Revenue!V11:Y11),1) | F11: =SUM(Revenue!Z14:AC14)/MAX(SUM(Revenue!Z11:AC11),1)
A12: Less: Infrastructure | B12: =-SUM(Costs!B10:M10) | C12: =-SUM(Costs!N10:Q10) | D12: =-SUM(Costs!R10:U10) | E12: =-SUM(Costs!V10:Y10) | F12: =-SUM(Costs!Z10:AC10) | G12: =SUM(B12:F12)
A13: Less: OpEx (marketing+legal+salaries) | B13: =-SUM(Costs!B16:M16) | C13: =-SUM(Costs!N16:Q16) | D13: =-SUM(Costs!R16:U16) | E13: =-SUM(Costs!V16:Y16) | F13: =-SUM(Costs!Z16:AC16) | G13: =SUM(B13:F13)
A14: EBITDA | B14: =B10+B12+B13 | C14: =C10+C12+C13 | D14: =D10+D12+D13 | E14: =E10+E12+E13 | F14: =F10+F12+F13 | G14: =SUM(B14:F14)
A15: EBITDA margin % | B15: =B14/MAX(B8,1) | C15: =C14/MAX(C8,1) | D15: =D14/MAX(D8,1) | E15: =E14/MAX(E8,1) | F15: =F14/MAX(F8,1)
A16: Cumulative EBITDA | B16: =B14 | C16: =B16+C14 | D16: =C16+D14 | E16: =D16+E14 | F16: =E16+F14 | G16: =F16

Sheet CashFlow
A1: Cash flow — monthly Y1, quarterly Y2–Y5
A2: Simple cash view — PayFast payout 3–5 business days assumed. No investment funding modelled.
A4: Metric | B4: Y1 M1 | C4: Y1 M2 | D4: Y1 M3 | E4: Y1 M4 | F4: Y1 M5 | G4: Y1 M6 | H4: Y1 M7 | I4: Y1 M8 | J4: Y1 M9 | K4: Y1 M10 | L4: Y1 M11 | M4: Y1 M12 | N4: Y2 Q1 | O4: Y2 Q2 | P4: Y2 Q3 | Q4: Y2 Q4 | R4: Y3 Q1 | S4: Y3 Q2 | T4: Y3 Q3 | U4: Y3 Q4 | V4: Y4 Q1 | W4: Y4 Q2 | X4: Y4 Q3 | Y4: Y4 Q4 | Z4: Y5 Q1 | AA4: Y5 Q2 | AB4: Y5 Q3 | AC4: Y5 Q4
A5: Cash inflow (net after PayFast) | B5: =Revenue!B14 | C5: =Revenue!C14 | D5: =Revenue!D14 | E5: =Revenue!E14 | F5: =Revenue!F14 | G5: =Revenue!G14 | H5: =Revenue!H14 | I5: =Revenue!I14 | ... AC5: =Revenue!AC14
A6: Cash outflow (infra + OpEx) | B6: =-Costs!B10-Costs!B16 | C6: =-Costs!C10-Costs!C16 | D6: =-Costs!D10-Costs!D16 | E6: =-Costs!E10-Costs!E16 | F6: =-Costs!F10-Costs!F16 | G6: =-Costs!G10-Costs!G16 | H6: =-Costs!H10-Costs!H16 | I6: =-Costs!I10-Costs!I16 | ... AC6: =-Costs!AC10-Costs!AC16
A7: VAT remitted to SARS | B7: =-Revenue!B10 | C7: =-Revenue!C10 | D7: =-Revenue!D10 | E7: =-Revenue!E10 | F7: =-Revenue!F10 | G7: =-Revenue!G10 | H7: =-Revenue!H10 | I7: =-Revenue!I10 | ... AC7: =-Revenue!AC10
A8: Net cash flow (period) | B8: =B5+B6+B7 | C8: =C5+C6+C7 | D8: =D5+D6+D7 | E8: =E5+E6+E7 | F8: =F5+F6+F7 | G8: =G5+G6+G7 | H8: =H5+H6+H7 | I8: =I5+I6+I7 | ... AC8: =AC5+AC6+AC7
A9: Opening cash | B9: 0 | C9: =B10 | D9: =C10 | E9: =D10 | F9: =E10 | G9: =F10 | H9: =G10 | I9: =H10 | J9: =I10 | ... AC9: =AB10
A10: Closing cash | B10: =B9+B8 | C10: =C9+C8 | D10: =D9+D8 | E10: =E9+E8 | F10: =F9+F8 | G10: =G9+G8 | H10: =H9+H8 | I10: =I9+I8 | ... AC10: =AC9+AC8

Sheet Scenarios
A1: Unit economics & scenario comparison
A3: Unit economics (active scenario)
A4: ARPU (monthly, active prac, ZAR ex-VAT) | B4: =plans_per_prac*credits_per_plan*rev_per_credit/credit_consume/(1+vat)
A5: Gross margin % | B5: =1-pf_pct_early
A6: Monthly gross profit / active prac (ZAR) | B6: =B4*B5
A7: Avg lifetime months (1/churn) | B7: =1/churn
A8: LTV (ZAR) | B8: =B6*B7
A9: Blended CAC (ZAR) | B9: =mix_warm*0+mix_paid*paid_cac_sa+mix_ref*ref_cost
A10: LTV / CAC | B10: =B8/MAX(B9,1)
A11: CAC payback (months) | B11: =B9/MAX(B6,1)
A12: Pricing ROI for practitioner (session-value) | B12: =650*5*0.05*52/12/B4
A14: Scenario snapshot (Y5 rollup)
A15: Metric | B15: Conservative (scn=1) | C15: Base (scn=2) | D15: Optimistic (scn=3)
A16: Y5 end paying practitioners | C16: =Growth!AC16
A17: Y5 gross revenue (ZAR) | C17: =SUM(Revenue!Z9:AC9)
A18: Y5 EBITDA (ZAR) | C18: ='P&L'!F14
A19: Y5 EBITDA margin | C19: ='P&L'!F15
A20: Cumulative 5-yr EBITDA (ZAR) | C20: ='P&L'!F16
A22: To compare scenarios: toggle Assumptions!C5 (Active scenario) to 1, 2, or 3.
A23: Then snapshot Y5 numbers manually into column B or D.
A25: Precomputed snapshots (from build — tweak inputs then resnap)
A26: Note: Values in cols B/D are TEXT placeholders; they don't auto-update. Use col C (live).

Sheet Sensitivity
A1: Sensitivity — which assumptions move Y5 EBITDA most
A3: Tornado-style table. Each row measures Y5 EBITDA (Base) when a single input is flexed to Conservative (-) or Optimistic (+). See README for interpretation. Values pull live from the model as you toggle Assumptions!C5.
A5: Driver | B5: Base Y5 EBITDA | C5: Conservative Y5 EBITDA | D5: Optimistic Y5 EBITDA | E5: Swing (cons → opt)
A6: Plans per practitioner per month | B6: (live — toggle scn=2) | C6: (swap cons input only, re-snap) | D6: (swap opt input only, re-snap) | E6: =D - C when filled
A7: Monthly churn | B7: (live — toggle scn=2) | C7: (swap cons input only, re-snap) | D7: (swap opt input only, re-snap) | E7: =D - C when filled
A8: Paid CAC (SA) | B8: (live — toggle scn=2) | C8: (swap cons input only, re-snap) | D8: (swap opt input only, re-snap) | E8: =D - C when filled
A9: Signup rate (reachable → signup) | B9: (live — toggle scn=2) | C9: (swap cons input only, re-snap) | D9: (swap opt input only, re-snap) | E9: =D - C when filled
A10: Revenue per credit | B10: (live — toggle scn=2) | C10: (swap cons input only, re-snap) | D10: (swap opt input only, re-snap) | E10: =D - C when filled
A11: International expansion start year | B11: (live — toggle scn=2) | C11: (swap cons input only, re-snap) | D11: (swap opt input only, re-snap) | E11: =D - C when filled
A12: Founder salary | B12: (live — toggle scn=2) | C12: (swap cons input only, re-snap) | D12: (swap opt input only, re-snap) | E12: =D - C when filled
A13: Marketing spend floor | B13: (live — toggle scn=2) | C13: (swap cons input only, re-snap) | D13: (swap opt input only, re-snap) | E13: =D - C when filled
A16: Live Y5 EBITDA (active scenario) | B16: ='P&L'!F14
